<?xml version="1.0"?>
<robot name="pdsrooz" xmlns:xacro="http://www.ros.org/wiki/xacro">

  <!-- Declaration of the constants used in description -->

  <xacro:property name="mu" value="1" />
  <xacro:property name="kp" value="1e+13" />
  <xacro:property name="kd" value="1" />
  <xacro:property name="camera_link" value="0.05" />

<!-- Including dependences to work with Gazebo and materials to work with Rviz -->

  <xacro:include filename="$(find pdsrooz_description)/urdf/pdsrooz.gazebo" />
  <xacro:include filename="$(find pdsrooz_description)/urdf/materials.xacro" />

<!-- Links description -->

  <!-- Dummy Link -->

  <link name="base_link" />

  <joint name="base_link_to_case" type="fixed">
    <parent link="base_link"/>
    <child link="case_link"/>
  </joint>

  <!-- Spherical case link -->

  <link name="case_link">
    <visual>
      <geometry>
        <mesh filename="package://pdsrooz_description/meshes/case_PDSR.dae"/>
      </geometry>
      <material name="color_case"/>
      <origin xyz="0 0 0.2" rpy="0 0 0"/>
    </visual>
    <collision>
      <geometry>
        <mesh filename="package://pdsrooz_description/meshes/case_PDSR.dae"/>
      </geometry>
      <origin xyz="0 0 0.2" rpy="0 0 0"/>
      <contact_coefficients mu="${mu}" kp="${kp}" kd="${kd}"/>
    </collision>
    <inertial>
      <origin xyz="0 0 0.2" rpy="0 0 0"/>
      <!--origin xyz="2.0588000000e-04  7.2010000000e-05  ${0.2 + 7.0420000000e-05}" rpy="0 0 0" /-->
      <mass value="0.5" />
      <inertia
        ixx="1.3333333333e-02" ixy="0" ixz="0"
        iyy="1.3333333333e-02" iyz="0"
        izz="1.3333333333e-02" />
      <!--inertia
			  ixx="1.3024654351e-02" ixy="-4.0686824703e-06" ixz="-3.6544396711e-06"
				iyy="1.3006953499e-02" iyz="-3.4803044650e-06"
				izz="1.3015192835e-02" /-->
      <!--inertia
        ixx="0.536165" ixy="0" ixz ="0"
        iyy="0.536165" iyz="0"
        izz="0.536165"/ -->
      <!--inertia
        ixx="0.0093037365783076" ixy="0" ixz="0"
        iyy="0.0093037365783076" iyz="0"
        izz="0.0093037365783076"/-->
      <!--inertia
        ixx="0" ixy="0" ixz="0"
        iyy="0" iyz="0"
        izz="0"/-->
    </inertial>
  </link>

  <!-- Trasnversal shaft link -->

  <link name="axis_link">
    <visual>
      <geometry>
        <mesh filename="package://pdsrooz_description/meshes/axis_PDSR.dae" />
      </geometry>
      <material name="solid_grey"/>
      <origin xyz="0 0 0" rpy="0 0 0"/>
    </visual>
    <collision>
      <geometry>
        <mesh filename="package://pdsrooz_description/meshes/axis_PDSR.dae" />
      </geometry>
      <contact_coefficients mu="${mu}" kp="${kp}" kd="${kd}" />
    </collision>
    <inertial>
      <!--origin  xyz="1.1100000000e-06 -3.0000000000e-08 -0.0000000000e+00" rpy="0 0 0" /-->
      <origin xyz="0 0 0" rpy="0 0 0"/>
      <mass value="0.1" />
			<!--inertia
        ixx="3.1787797372e-07" ixy="-8.8499222247e-12" ixz="0.0000000000e+00"
        iyy="1.3414771222e-04" iyz=" 0.0000000000e+00"
        izz="1.3414789689e-04" /-->
      <!--inertia
        izz="0.00167866"      ixy="0"     ixz="0"
        ixx="6.28319e-06"     iyz="0"
        iyy="0.00167866" /-->
      <inertia
        ixx="3.2e-06" ixy="0" ixz="0"
        iyy="0.0013" iyz="0"
        izz="0.0013"/>
      <!--inertia
        ixx="0" ixy="0" ixz="0"
        iyy="0" iyz="0"
        izz="0"/-->
    </inertial>
  </link>

  <!-- Pendulum link -->

  <link name="rod_link">
    <visual>
      <geometry>
        <mesh filename="package://pdsrooz_description/meshes/pendulum_PDSR.dae" />
      </geometry>
      <material name="solid_grey"/>
      <origin xyz="0 0 0" rpy="0 0 0"/>
    </visual>
    <collision>
      <geometry>
        <mesh filename="package://pdsrooz_description/meshes/pendulum_PDSR.dae" />
      </geometry>
      <contact_coefficients mu="${mu}" kp="${kp}" kd="${kd}" />
    </collision>
    <inertial>
      <origin xyz="0 0 -0.15" />
      <!--origin xyz="-0.0000000000e+00 -0.0000000000e+00 -9.0000000000e-02" rpy="0 0 0" /-->
      <mass value="0.639" />
			<!--inertia
				ixx="1.8676830030e-03" ixy="0.0000000000e+00" ixz="0.0000000000e+00"
				iyy="1.8676830030e-03" iyz="0.0000000000e+00"
				izz="2.8476475065e-04" /-->
      <!--inertia
        ixx="4.0715e-05" ixy="0" ixz="0"
        iyy="4.0715e-05" iyz="0"
        izz="4.0715e-05"/-->
      <!--inertia
        ixx="1.6760807315446848e-06" ixy="0" ixz="0"
        iyy="1.6760807315446848e-06" iyz="0"
        izz="1.6760807315446848e-06"/-->
      <inertia
        ixx="0.00023004" ixy="0" ixz="0"
        iyy="0.00023004" iyz="0"
        izz="0.00023004"/>
		</inertial>
  </link>

    <!-- Camera link -->

  <!--link name="camera_link">
    <visual>
      <geometry>
        <box size="${camera_link} ${camera_link} ${camera_link}" />
      </geometry>
      <material name="solid_grey" />
      <origin xyz="0 0 0" rpy="0 0 0" />
    </visual>
    <collision>
      <geometry>
        <box size="${camera_link} ${camera_link} ${camera_link}" />
      </geometry>
      <origin xyz="0 0 0" rpy="0 0 0" />
    </collision>
    <inertial>
      <mass value="1.0000000000e-05" />
      <origin xyz="0 0 0" rpy="0 0 0" />
      <inertia
        ixx="4.1666660160e-09" ixy="0.0000000000e+00" ixz="0.0000000000e+00"
        iyy="4.1666660160e-09" iyz="0.0000000000e+00"
        izz="4.1666660160e-09" />
    </inertial>
  </link-->

  <!-- Loss Weight Link-->

  <!--link name="weight_link">
    <visual>
      <geometry>
        <box size="${camera_link} ${camera_link} ${camera_link}" />
      </geometry>
      <material name="solid_grey" />
      <origin xyz="0 0 0" rpy="0 0 0" />
    </visual>
    <collision>
      <geometry>
        <box size="${camera_link} ${camera_link} ${camera_link}" />
      </geometry>
      <origin xyz="0 0 0" rpy="0 0 0" />
    </collision>
    <inertial>
      <mass value="1.0000000000e-05" />
      <origin xyz="0 0 0" rpy="0 0 0" />
      <inertia
        ixx="4.1666660160e-09" ixy="0.0000000000e+00" ixz="0.0000000000e+00"
        iyy="4.1666660160e-09" iyz="0.0000000000e+00"
        izz="4.1666660160e-09" />
    </inertial>
  </link-->

<!-- Joints description -->

  <!-- Joint used to join the external case to the transversal shaft -->

  <joint name="case_to_axis" type="continuous">
    <parent link="case_link"/>
    <child link="axis_link"/>
    <axis xyz="1 0 0"/>
    <origin xyz="0 0 0.2" rpy="0 0 0"/>
  </joint>

  <!-- Joint used to join the transversal shaft to the pendulum -->

  <joint name="axis_to_rod" type="continuous">
    <parent link="axis_link"/>
    <child link="rod_link"/>
    <axis xyz="0 1 0" />
    <!--limit effort="0.0" velocity="0.0" lower="0.0" upper="0.0" /-->
    <origin xyz="0 0 0" rpy="0 0 0"/>
  </joint>

  <!-- Joint used to join the transversal shaft and the camera -->

  <!--joint name="axis_to_camera" type="revolute">
    <axis xyz="0 1 0" />
    <parent link="axis_link" />
    <child link="camera_link" />
    <limit effort="0.0" velocity="0.0" lower="0.0" upper="0.0" />
    <origin xyz="${0.2 + camera_link/2} 0 0" rpy="0 0 1.5708" />
  </joint-->

  <!--joint name="axis_to_weight" type="revolute">
    <axis xyz="0 1 0"/>
    <parent link="axis_link" />
    <child link="weight_link" />
    <limit effort="0.0" velocity="0.0" lower="0.0" upper="0.0" />
    <origin xyz="${-0.2 - camera_link/2} 0 0" rpy="0 0 0"/>
  </joint-->

<!-- Definition of the control parameters (Transmissions, acutators, and so on) -->

  <!--Transmission for the first joint (case joins to transversal shaft)-->

  <transmission name="trans1">
    <type>transmission_interface/SimpleTransmission</type>
    <joint name="case_to_axis">
      <hardwareInterface>hardware_interface/EffortJointInterface</hardwareInterface>
    </joint>
    <actuator name="long_motor">
      <hardwareInterface>EffortJointInterface</hardwareInterface>
      <mechanicalReduction>1</mechanicalReduction>
    </actuator>
  </transmission>

  <!--TRansmission for the second joint (transversal shaft joins to pendulum)-->

  <transmission name="trans2">
    <type>transmission_interface/SimpleTransmission</type>
    <joint name="axis_to_rod">
      <hardwareInterface>hardware_interface/EffortJointInterface</hardwareInterface>
    </joint>
    <actuator name="steer_motor">
      <hardwareInterface>EffortJointInterface</hardwareInterface>
      <mechanicalReduction>1</mechanicalReduction>
    </actuator>
  </transmission>

</robot>
